Workbook

Sheet MenuItems
A1: id | B1: name | C1: ingredients | D1: englishTranslation | E1: germanTranslation | F1: firstPrice | G1: secondPrice | H1: order | I1: category | J1: menuSection | K1: subcategory | L1: menuFormats
A2: 1 | B2: Marinara | C2: pomodoro pelato italiano, origano calabrese, aglio tritato ﬁne, olio extravergine di oliva 100% italiano, basilico fresco | D2: peeled Italian tomatoes, Calabrian oregano, finely chopped garlic, 100% Italian extra virgin olive oil, fresh basil | E2: geschälte italienische Tomaten, kalabrischer Oregano, fein gehackter Knoblauch, 100 % italienisches natives Olivenöl extra, frisches Basilikum | F2: 6.5 | H2: 1 | I2: 1 | J2: =VLOOKUP(I2, MenuSections!$A$2:$B$13, 2, FALSE) -> Specialty | L2: 1,2,3
A3: 2 | B3: Bufala | C3: pomodoro pelato italiano, mozzarella di bufala campana DOP, parmigiano reggiano, olio extravergine 100% italiano, basilico fresco | D3: peeled Italian tomatoes, buffalo mozzarella from Campania DOP, Parmigiano Reggiano, 100% Italian extra virgin olive oil, fresh basil | E3: geschälte italienische Tomaten, Büffelmozzarella aus Kampanien DOP, Parmigiano Reggiano, 100 % italienisches natives Olivenöl extra, frisches Basilikum | F3: 10.5 | H3: 2 | I3: 1 | J3: =VLOOKUP(I3, MenuSections!$A$2:$B$13, 2, FALSE) -> Specialty | L3: 1,2,3
A4: 3 | B4: Veneta | C4: base bianca senza pomodoro, mozzarella da latte 100% italiano, provola affumicata, gocce di olio aromatizzato al tartufo, porchetta trevigiana selezione oro a ﬁne cottura | D4: white base without tomato, mozzarella from 100% Italian milk, smoked provola cheese, drops of truffle-flavored oil, premium Treviso porchetta added after baking | E4: Weiße Basis ohne Tomate, Mozzarella aus 100 % italienischer Milch, geräucherter Provola, Tropfen von Trüffelöl, Treviso-Porchetta „Selezione Oro“ nach dem Backen | F4: 12.5 | H4: 3 | I4: 1 | J4: =VLOOKUP(I4, MenuSections!$A$2:$B$13, 2, FALSE) -> Specialty | L4: 1,2,3
A5: 4 | B5: Saporita | C5: base bianca senza pomodoro, mozzarella da latte 100% italiano, gorgonzola DOP, grana padano DOP grattuggiato, prosciutto cotto alta qualità a ﬁne cottura | D5: white base without tomato, mozzarella from 100% Italian milk, Gorgonzola DOP, grated Grana Padano DOP, premium cooked ham added after baking | E5: Weiße Basis ohne Tomate, Mozzarella aus 100 % italienischer Milch, Gorgonzola DOP, geriebener Grana Padano DOP, hochwertiger Kochschinken nach dem Backen | F5: 12.5 | H5: 4 | I5: 1 | J5: =VLOOKUP(I5, MenuSections!$A$2:$B$13, 2, FALSE) -> Specialty | L5: 1,2,3
A6: 5 | B6: Sarda | C6: pomodoro pelato italiano, origano calabrese, mozzarella da latte 100% italiano, salsiccia di maiale senza conservanti aggiunti, pecorino sardo DOP grattuggiato (in cottura) | D6: Italian peeled tomatoes, Calabrian oregano, mozzarella from 100% Italian milk, preservative-free pork sausage, grated Pecorino Sardo DOP (cooked) | E6: Italienische geschälte Tomaten, kalabrischer Oregano, Mozzarella aus 100 % italienischer Milch, Schweinswurst ohne Zusatzstoffe, geriebener Pecorino Sardo DOP (mitgebacken) | F6: 11.5 | H6: 5 | I6: 1 | J6: =VLOOKUP(I6, MenuSections!$A$2:$B$13, 2, FALSE) -> Specialty | L6: 1,2,3
A7: 6 | B7: Bologna | C7: base bianca senza pomodoro, mozzarella da latte 100% italiano, mortadella IGP antica bologna, stracciatella di burrata, granella di pistacchio | D7: white base without tomato, mozzarella from 100% Italian milk, "Antica Bologna" Mortadella IGP, burrata stracciatella, crushed pistachios | E7: Weiße Basis ohne Tomate, Mozzarella aus 100 % italienischer Milch, Mortadella IGP „Antica Bologna“, Stracciatella di Burrata, gehackte Pistazien | F7: 13 | H7: 6 | I7: 1 | J7: =VLOOKUP(I7, MenuSections!$A$2:$B$13, 2, FALSE) -> Specialty | L7: 1,2,3
A8: 7 | B8: Gricia | C8: base bianca senza pomodoro, mozzarella da latte 100% italiano, pecorino Romano DOP grattugiato, guanciale di Sauris, pepe nero macinato a ﬁne cottura | D8: white base without tomato, mozzarella from 100% Italian milk, grated Pecorino Romano DOP, Sauris guanciale, freshly ground black pepper added after baking | E8: Weiße Basis ohne Tomate, Mozzarella aus 100 % italienischer Milch, geriebener Pecorino Romano DOP, Guanciale aus Sauris, schwarzer Pfeffer nach dem Backen | F8: 11.5 | H8: 7 | I8: 1 | J8: =VLOOKUP(I8, MenuSections!$A$2:$B$13, 2, FALSE) -> Specialty | L8: 1,2,3
A9: 8 | B9: Salsiccia e friarielli | C9: base bianca senza pomodoro, mozzarella da latte 100% italiano, friarielli*, salsiccia senza conservanti aggiunti, provola affumicata, grana padano DOP | D9: white base without tomato, mozzarella from 100% Italian milk, *friarielli (Neapolitan-style broccoli rabe), preservative-free sausage, smoked provola cheese, Grana Padano DOP | E9: Weiße Basis ohne Tomate, Mozzarella aus 100 % italienischer Milch, *friarielli*, Wurst ohne Zusatzstoffe, geräucherter Provola, Grana Padano DOP | F9: 12 | H9: 8 | I9: 1 | J9: =VLOOKUP(I9, MenuSections!$A$2:$B$13, 2, FALSE) -> Specialty | L9: 1,2,3
A10: 9 | B10: Siciliana | C10: pomodoro pelato italiano, mozzarella di bufala campana DOP, olive della Riviera del Garda denocciolate, capperi siciliani, ﬁletti di acciughe, origano, basilico fresco | D10: Italian peeled tomatoes, buffalo mozzarella from Campania DOP, pitted olives from Lake Garda, Sicilian capers, anchovy fillets, oregano, fresh basil | E10: Italienische geschälte Tomaten, Büffelmozzarella aus Kampanien DOP, entkernte Oliven von der Gardasee-Riviera, sizilianische Kapern, Sardellenfilets, Oregano, frisches Basilikum | F10: 13 | H10: 9 | I10: 1 | J10: =VLOOKUP(I10, MenuSections!$A$2:$B$13, 2, FALSE) -> Specialty | L10: 1,2,3
A11: 10 | B11: Parma Dop | C11: pomodoro pelato italiano, mozzarella con latte di bufala campana DOP spezzata a mano, crudo di Parma riserva DOP stagionato 24 mesi, basilico fresco | D11: peeled Italian tomatoes, hand-shredded mozzarella made with buffalo milk from Campania (PDO), 24-month-aged Parma ham (PDO), fresh basil | E11: geschälte italienische Tomaten, handgezupfter Mozzarella aus Büffelmilch aus Kampanien (g.U.), 24 Monate gereifter Parmaschinken „Riserva“ (g.U.), frisches Basilikum | F11: 13 | H11: 10 | I11: 1 | J11: =VLOOKUP(I11, MenuSections!$A$2:$B$13, 2, FALSE) -> Specialty | L11: 1,2,3
A12: 11 | B12: Tirolese | C12: crema di ricotta alla base, mozzarella da latte 100% italiano, formaggio brie, speck di Sauris IGP | D12: ricotta cream base, mozzarella from 100% Italian milk, Brie cheese, Sauris speck IGP | E12: Ricottacreme als Basis, Mozzarella aus 100 % italienischer Milch, Brie, Speck aus Sauris IGP | F12: 13 | H12: 11 | I12: 1 | J12: =VLOOKUP(I12, MenuSections!$A$2:$B$13, 2, FALSE) -> Specialty | L12: 1,2,3
A13: 12 | B13: Capricciosa | C13: salsa di pomodoro, mozzarella ﬁor di latte, prosciutto cotto alta qualità, carcioﬁ, funghi champignon trifolati | D13: tomato sauce, fior di latte mozzarella, premium cooked ham, artichokes, sautéed champignon mushrooms | E13: Tomatensoße, Fior di Latte-Mozzarella, hochwertiger Kochschinken, Artischocken, sautierte Champignon-Pilze | F13: 10.5 | H13: 12 | I13: 2 | J13: =VLOOKUP(I13, MenuSections!$A$2:$B$13, 2, FALSE) -> Classic | L13: 1,2,3
... A21: 20 | B21: Parmigiana | C21: pomodoro pelato italiano, mozzarella da latte 100% italiano, melanzane cotte in forno a bassa temperatura, parmigiano reggiano grattuggiato in cottura, basilico fresco | D21: Italian peeled tomatoes, mozzarella from 100% Italian milk, slow-roasted eggplant, grated Parmigiano Reggiano (cooked), fresh basil | E21: Italienische geschälte Tomaten, Mozzarella aus 100 % italienischer Milch, bei niedriger Temperatur gebackene Auberginen, geriebener Parmigiano Reggiano (mitgebacken), frisches Basilikum | F21: 11 | H21: 20 | I21: 2 | J21: =VLOOKUP(I21, MenuSections!$A$2:$B$13, 2, FALSE) -> Classic | L21: 1,2,3
A22: 21 | B22: Prosecco DOCG extra dry | D22: Prosecco DOCG extra dry | F22: 3.5 | H22: 21 | I22: 3 | J22: =VLOOKUP(I22, MenuSections!$A$2:$B$13, 2, FALSE) -> Aperitif | L22: 1,2
A23: 22 | B23: Prosecco DOCG brut | D23: Prosecco DOCG brut | F23: 3.5 | H23: 22 | I23: 3 | J23: =VLOOKUP(I23, MenuSections!$A$2:$B$13, 2, FALSE) -> Aperitif | L23: 1,2
A24: 23 | B24: Americano | D24: Americano | F24: 6 | H24: 23 | I24: 3 | J24: =VLOOKUP(I24, MenuSections!$A$2:$B$13, 2, FALSE) -> Aperitif | L24: 1,2
A25: 24 | B25: Gin Tonic | D25: Gin Tonic | F25: 7.5 | G25: 10 | H25: 24 | I25: 3 | J25: =VLOOKUP(I25, MenuSections!$A$2:$B$13, 2, FALSE) -> Aperitif | L25: 1,2
A26: 25 | B26: Vodka Tonic | D26: Vodka Tonic | F26: 7.5 | G26: 10 | H26: 25 | I26: 3 | J26: =VLOOKUP(I26, MenuSections!$A$2:$B$13, 2, FALSE) -> Aperitif | L26: 1,2
A27: 26 | B27: Rum e cola | D27: Rum and cola | F27: 8.5 | H27: 26 | I27: 3 | J27: =VLOOKUP(I27, MenuSections!$A$2:$B$13, 2, FALSE) -> Aperitif | L27: 1,2
A28: 27 | B28: Spritz Aperol | D28: Spritz Aperol | F28: 4 | H28: 27 | I28: 3 | J28: =VLOOKUP(I28, MenuSections!$A$2:$B$13, 2, FALSE) -> Aperitif | L28: 1,2
A29: 28 | B29: Spritz Campari | D29: Spritz Campari | F29: 4 | H29: 28 | I29: 3 | J29: =VLOOKUP(I29, MenuSections!$A$2:$B$13, 2, FALSE) -> Aperitif | L29: 1,2
A30: 29 | B30: Spritz bianco | D30: White Spritz | F30: 3.5 | H30: 29 | I30: 3 | J30: =VLOOKUP(I30, MenuSections!$A$2:$B$13, 2, FALSE) -> Aperitif | L30: 1,2
A31: 30 | B31: Gingerino biologico | D31: Organic ginger | F31: 3.5 | H31: 30 | I31: 3 | J31: =VLOOKUP(I31, MenuSections!$A$2:$B$13, 2, FALSE) -> Aperitif | L31: 1,2
A32: 31 | B32: Analcolico San Michele | D32: Non-alcoholic San Michele | F32: 3.5 | H32: 31 | I32: 3 | J32: =VLOOKUP(I32, MenuSections!$A$2:$B$13, 2, FALSE) -> Aperitif | L32: 1,2
A33: 32 | B33: Acqua naturale/frizzante 0,75l | D33: Still and sparkling water 0,75l | E33: Stilles/Sprudelndes Wasser 0,75l | F33: 3.5 | H33: 32 | I33: 4 | J33: =VLOOKUP(I33, MenuSections!$A$2:$B$13, 2, FALSE) -> Drink | L33: 1,2
A34: 33 | B34: Coca Cola 0,3l | F34: 3.5 | H34: 33 | I34: 4 | J34: =VLOOKUP(I34, MenuSections!$A$2:$B$13, 2, FALSE) -> Drink | L34: 1,2
A35: 34 | B35: Coca Cola 0,5l | F35: 5 | H35: 34 | I35: 4 | J35: =VLOOKUP(I35, MenuSections!$A$2:$B$13, 2, FALSE) -> Drink | L35: 1,2
A36: 35 | B36: Coca Cola Zero | D36: Coca Cola Zero Sugar | F36: 3.5 | H36: 35 | I36: 4 | J36: =VLOOKUP(I36, MenuSections!$A$2:$B$13, 2, FALSE) -> Drink | L36: 1,2
A37: 36 | B37: Fanta | D37: Fanta | F37: 3.5 | H37: 36 | I37: 4 | J37: =VLOOKUP(I37, MenuSections!$A$2:$B$13, 2, FALSE) -> Drink | L37: 1,2
A38: 37 | B38: Fever Tree Tonica | D38: Fever Tree Tonic | F38: 3.5 | H38: 37 | I38: 4 | J38: =VLOOKUP(I38, MenuSections!$A$2:$B$13, 2, FALSE) -> Drink | L38: 1,2
A39: 38 | B39: The San Benedetto in vetro | D39: Glass San Benedetto tea | E39: San Benedetto Eistee (Glasflasche) | F39: 3.5 | H39: 38 | I39: 4 | J39: =VLOOKUP(I39, MenuSections!$A$2:$B$13, 2, FALSE) -> Drink | L39: 1,2
A40: 39 | B40: Coca Cola in lattina | F40: 2 | H40: 39 | I40: 4 | J40: =VLOOKUP(I40, MenuSections!$A$2:$B$13, 2, FALSE) -> Drink | L40: 3
A41: 40 | B41: Birra Paulaner in bottiglia 0,33l | F41: 2.5 | H41: 40 | I41: 4 | J41: =VLOOKUP(I41, MenuSections!$A$2:$B$13, 2, FALSE) -> Drink | L41: 3
A42: 41 | B42: Bionda Paulaner Munchner Hell | D42: Blonde Paulaner Munchner Hell | E42: Paulaner Munchner Hell | F42: 3.5 | G42: 5.5 | H42: 41 | I42: 5 | J42: =VLOOKUP(I42, MenuSections!$A$2:$B$13, 2, FALSE) -> DraftBeer | L42: 1,2
A43: 42 | B43: Non Filtrata Schwechater Zwickl | D43: Unfiltered Schwechater Zwickl | E43: Schwechater Zwickl | F43: 3.5 | G43: 6 | H43: 42 | I43: 5 | J43: =VLOOKUP(I43, MenuSections!$A$2:$B$13, 2, FALSE) -> DraftBeer | L43: 1,2
A44: 43 | B44: Rossa Paulaner Salvator | D44: Red Paulaner Salvator | E44: Paulaner Salvator | F44: 3.5 | G44: 6 | H44: 43 | I44: 5 | J44: =VLOOKUP(I44, MenuSections!$A$2:$B$13, 2, FALSE) -> DraftBeer | L44: 1,2
A45: 44 | B45: Bianca Blanche de Namur 0,33l | F45: 5 | H45: 44 | I45: 6 | J45: =VLOOKUP(I45, MenuSections!$A$2:$B$13, 2, FALSE) -> BottleBeer | L45: 1,2
A46: 45 | B46: Herb Radler Cimbra 0,5l | F46: 6.5 | H46: 45 | I46: 6 | J46: =VLOOKUP(I46, MenuSections!$A$2:$B$13, 2, FALSE) -> BottleBeer | L46: 1,2
A47: 46 | B47: Weizen Andechs 0,5l | F47: 6.5 | H47: 46 | I47: 6 | J47: =VLOOKUP(I47, MenuSections!$A$2:$B$13, 2, FALSE) -> BottleBeer | L47: 1,2
...

Sheet MenuSections
A1: id | B1: name
A2: 1 | B2: Specialty
A3: 2 | B3: Classic
A4: 3 | B4: Aperitif
A5: 4 | B5: Drink
A6: 5 | B6: DraftBeer
A7: 6 | B7: BottleBeer
A8: 7 | B8: Wine
A9: 8 | B9: Cake
A10: 9 | B10: Cocktail
A11: 10 | B11: Digestif
A12: 11 | B12: Grappa
A13: 12 | B13: Coffee

Sheet MenuFormat
A1: id | B1: name
A2: 1 | B2: Complete
A3: 2 | B3: Table
A4: 3 | B4: TakeAway
A5: 4 | B5: Dessert
